"{\"success\":false,\"header\":null,\"data\":null,\"messageKey\":\"error.500\",\"message\":\"error.500\",\"errors\":[],\"exceptions\":[{\"messageData\":{},\"resource\":\"Throwable\",\"messageKey\":\"Throwable\",\"message\":\"Throwable with cause of type 'com.manh.cp.fw.core.exception.ManhRuntimeException' was caught and handled by CustomErrorController (see logs for the trace)\",\"stackTrace\":\"java.lang.Throwable: Throwable with cause of type 'com.manh.cp.fw.core.exception.ManhRuntimeException' was caught and handled by CustomErrorController (see logs for the trace)\\n\"}],\"messages\":{\"Message\":[],\"Size\":0},\"rootCause\":\"java.lang.Throwable: Throwable with cause of type 'com.manh.cp.fw.core.exception.ManhRuntimeException' was caught and handled by CustomErrorController (see logs for the trace)\",\"cloudComponent\":\"com-manh-cp-organization:docker,cloud,side,om-side:8080\",\"cloudComponentHostName\":\"c1a2c5cc041f\",\"requestUri\":\"/error\",\"statusCode\":\"INTERNAL_SERVER_ERROR\"}"